2019-08-16 16:16:41,831 ERROR: Exception on /explore [GET] [in /Users/peterhychan/.local/share/virtualenvs/flaskblog-s-89An1C/lib/python3.7/site-packages/flask/app.py:1891]
Traceback (most recent call last):
  File "/Users/peterhychan/.local/share/virtualenvs/flaskblog-s-89An1C/lib/python3.7/site-packages/flask/app.py", line 2446, in wsgi_app
    response = self.full_dispatch_request()
  File "/Users/peterhychan/.local/share/virtualenvs/flaskblog-s-89An1C/lib/python3.7/site-packages/flask/app.py", line 1951, in full_dispatch_request
    rv = self.handle_user_exception(e)
  File "/Users/peterhychan/.local/share/virtualenvs/flaskblog-s-89An1C/lib/python3.7/site-packages/flask/app.py", line 1820, in handle_user_exception
    reraise(exc_type, exc_value, tb)
  File "/Users/peterhychan/.local/share/virtualenvs/flaskblog-s-89An1C/lib/python3.7/site-packages/flask/_compat.py", line 39, in reraise
    raise value
  File "/Users/peterhychan/.local/share/virtualenvs/flaskblog-s-89An1C/lib/python3.7/site-packages/flask/app.py", line 1949, in full_dispatch_request
    rv = self.dispatch_request()
  File "/Users/peterhychan/.local/share/virtualenvs/flaskblog-s-89An1C/lib/python3.7/site-packages/flask/app.py", line 1935, in dispatch_request
    return self.view_functions[rule.endpoint](**req.view_args)
  File "/Users/peterhychan/.local/share/virtualenvs/flaskblog-s-89An1C/lib/python3.7/site-packages/flask_login/utils.py", line 261, in decorated_view
    return func(*args, **kwargs)
  File "/Users/peterhychan/Desktop/flaskblog/app/routes.py", line 145, in explore
    if posts.has_next else None
UnboundLocalError: local variable 'posts' referenced before assignment
2019-08-16 16:16:57,281 ERROR: Exception on /explore [GET] [in /Users/peterhychan/.local/share/virtualenvs/flaskblog-s-89An1C/lib/python3.7/site-packages/flask/app.py:1891]
Traceback (most recent call last):
  File "/Users/peterhychan/.local/share/virtualenvs/flaskblog-s-89An1C/lib/python3.7/site-packages/flask/app.py", line 2446, in wsgi_app
    response = self.full_dispatch_request()
  File "/Users/peterhychan/.local/share/virtualenvs/flaskblog-s-89An1C/lib/python3.7/site-packages/flask/app.py", line 1951, in full_dispatch_request
    rv = self.handle_user_exception(e)
  File "/Users/peterhychan/.local/share/virtualenvs/flaskblog-s-89An1C/lib/python3.7/site-packages/flask/app.py", line 1820, in handle_user_exception
    reraise(exc_type, exc_value, tb)
  File "/Users/peterhychan/.local/share/virtualenvs/flaskblog-s-89An1C/lib/python3.7/site-packages/flask/_compat.py", line 39, in reraise
    raise value
  File "/Users/peterhychan/.local/share/virtualenvs/flaskblog-s-89An1C/lib/python3.7/site-packages/flask/app.py", line 1949, in full_dispatch_request
    rv = self.dispatch_request()
  File "/Users/peterhychan/.local/share/virtualenvs/flaskblog-s-89An1C/lib/python3.7/site-packages/flask/app.py", line 1935, in dispatch_request
    return self.view_functions[rule.endpoint](**req.view_args)
  File "/Users/peterhychan/.local/share/virtualenvs/flaskblog-s-89An1C/lib/python3.7/site-packages/flask_login/utils.py", line 261, in decorated_view
    return func(*args, **kwargs)
  File "/Users/peterhychan/Desktop/flaskblog/app/routes.py", line 145, in explore
    if posts.has_next else None
UnboundLocalError: local variable 'posts' referenced before assignment
2019-08-16 16:17:29,930 INFO: Microblog startup [in /Users/peterhychan/Desktop/flaskblog/app/__init__.py:42]
2019-08-16 16:17:36,810 ERROR: Exception on /explore [GET] [in /Users/peterhychan/.local/share/virtualenvs/flaskblog-s-89An1C/lib/python3.7/site-packages/flask/app.py:1891]
Traceback (most recent call last):
  File "/Users/peterhychan/.local/share/virtualenvs/flaskblog-s-89An1C/lib/python3.7/site-packages/flask/app.py", line 2446, in wsgi_app
    response = self.full_dispatch_request()
  File "/Users/peterhychan/.local/share/virtualenvs/flaskblog-s-89An1C/lib/python3.7/site-packages/flask/app.py", line 1951, in full_dispatch_request
    rv = self.handle_user_exception(e)
  File "/Users/peterhychan/.local/share/virtualenvs/flaskblog-s-89An1C/lib/python3.7/site-packages/flask/app.py", line 1820, in handle_user_exception
    reraise(exc_type, exc_value, tb)
  File "/Users/peterhychan/.local/share/virtualenvs/flaskblog-s-89An1C/lib/python3.7/site-packages/flask/_compat.py", line 39, in reraise
    raise value
  File "/Users/peterhychan/.local/share/virtualenvs/flaskblog-s-89An1C/lib/python3.7/site-packages/flask/app.py", line 1949, in full_dispatch_request
    rv = self.dispatch_request()
  File "/Users/peterhychan/.local/share/virtualenvs/flaskblog-s-89An1C/lib/python3.7/site-packages/flask/app.py", line 1935, in dispatch_request
    return self.view_functions[rule.endpoint](**req.view_args)
  File "/Users/peterhychan/.local/share/virtualenvs/flaskblog-s-89An1C/lib/python3.7/site-packages/flask_login/utils.py", line 261, in decorated_view
    return func(*args, **kwargs)
  File "/Users/peterhychan/Desktop/flaskblog/app/routes.py", line 135, in explore
    if posts.has_next else None
UnboundLocalError: local variable 'posts' referenced before assignment
2019-08-16 17:40:46,116 ERROR: Exception on /explore [GET] [in /Users/peterhychan/.local/share/virtualenvs/flaskblog-s-89An1C/lib/python3.7/site-packages/flask/app.py:1891]
Traceback (most recent call last):
  File "/Users/peterhychan/.local/share/virtualenvs/flaskblog-s-89An1C/lib/python3.7/site-packages/flask/app.py", line 2446, in wsgi_app
    response = self.full_dispatch_request()
  File "/Users/peterhychan/.local/share/virtualenvs/flaskblog-s-89An1C/lib/python3.7/site-packages/flask/app.py", line 1951, in full_dispatch_request
    rv = self.handle_user_exception(e)
  File "/Users/peterhychan/.local/share/virtualenvs/flaskblog-s-89An1C/lib/python3.7/site-packages/flask/app.py", line 1820, in handle_user_exception
    reraise(exc_type, exc_value, tb)
  File "/Users/peterhychan/.local/share/virtualenvs/flaskblog-s-89An1C/lib/python3.7/site-packages/flask/_compat.py", line 39, in reraise
    raise value
  File "/Users/peterhychan/.local/share/virtualenvs/flaskblog-s-89An1C/lib/python3.7/site-packages/flask/app.py", line 1949, in full_dispatch_request
    rv = self.dispatch_request()
  File "/Users/peterhychan/.local/share/virtualenvs/flaskblog-s-89An1C/lib/python3.7/site-packages/flask/app.py", line 1935, in dispatch_request
    return self.view_functions[rule.endpoint](**req.view_args)
  File "/Users/peterhychan/.local/share/virtualenvs/flaskblog-s-89An1C/lib/python3.7/site-packages/flask_login/utils.py", line 261, in decorated_view
    return func(*args, **kwargs)
  File "/Users/peterhychan/Desktop/flaskblog/app/routes.py", line 135, in explore
    next_url = url_for('explore', page=posts.next_num) \
UnboundLocalError: local variable 'posts' referenced before assignment
2019-08-16 17:40:48,899 ERROR: Exception on /explore [GET] [in /Users/peterhychan/.local/share/virtualenvs/flaskblog-s-89An1C/lib/python3.7/site-packages/flask/app.py:1891]
Traceback (most recent call last):
  File "/Users/peterhychan/.local/share/virtualenvs/flaskblog-s-89An1C/lib/python3.7/site-packages/flask/app.py", line 2446, in wsgi_app
    response = self.full_dispatch_request()
  File "/Users/peterhychan/.local/share/virtualenvs/flaskblog-s-89An1C/lib/python3.7/site-packages/flask/app.py", line 1951, in full_dispatch_request
    rv = self.handle_user_exception(e)
  File "/Users/peterhychan/.local/share/virtualenvs/flaskblog-s-89An1C/lib/python3.7/site-packages/flask/app.py", line 1820, in handle_user_exception
    reraise(exc_type, exc_value, tb)
  File "/Users/peterhychan/.local/share/virtualenvs/flaskblog-s-89An1C/lib/python3.7/site-packages/flask/_compat.py", line 39, in reraise
    raise value
  File "/Users/peterhychan/.local/share/virtualenvs/flaskblog-s-89An1C/lib/python3.7/site-packages/flask/app.py", line 1949, in full_dispatch_request
    rv = self.dispatch_request()
  File "/Users/peterhychan/.local/share/virtualenvs/flaskblog-s-89An1C/lib/python3.7/site-packages/flask/app.py", line 1935, in dispatch_request
    return self.view_functions[rule.endpoint](**req.view_args)
  File "/Users/peterhychan/.local/share/virtualenvs/flaskblog-s-89An1C/lib/python3.7/site-packages/flask_login/utils.py", line 261, in decorated_view
    return func(*args, **kwargs)
  File "/Users/peterhychan/Desktop/flaskblog/app/routes.py", line 135, in explore
    next_url = url_for('explore', page=posts.next_num) \
UnboundLocalError: local variable 'posts' referenced before assignment
